Workbook

Sheet Executive Summary
A1: Coal Market & Supply Analytics: Executive Summary
A2: Selected markets: China, India, Indonesia, Australia, Japan. All KPI values below are live formulas.
A4: Metric | B4: Value | C4: Basis
A5: Latest year of market data | B5: ='Market Trends'!$B$5 -> 2024 | C5: Market Trends
A6: Largest producer | B6: =INDEX('Market Trends'!$A$9:$A$13,MATCH(MAX('Market Trends'!$D$9:$D$13),'Market Trends'!$D$9:$D$13,0)) -> China | C6: Highest production, latest year
A7: production (Mt) | B7: =MAX('Market Trends'!$D$9:$D$13) -> 4780 | C7: Million tonnes
A8: share of selected-market production | B8: =MAX('Market Trends'!$G$9:$G$13) -> 0.66716914 | C8: Five selected countries only
A9: Fastest production growth | B9: =INDEX('Market Trends'!$A$9:$A$13,MATCH(MAX('Market Trends'!$E$9:$E$13),'Market Trends'!$E$9:$E$13,0)) -> Indonesia | C9: Full-period CAGR
A10: production CAGR | B10: =MAX('Market Trends'!$E$9:$E$13) -> 0.062012903
A11: Fastest consumption growth | B11: =INDEX('Market Trends'!$A$9:$A$13,MATCH(MAX('Market Trends'!$K$9:$K$13),'Market Trends'!$K$9:$K$13,0)) -> Indonesia | C11: Full-period CAGR (Indonesia affected by 2023 jump, see Data Quality)
A12: consumption CAGR | B12: =MAX('Market Trends'!$K$9:$K$13) -> 0.11494768
A13: Largest importer | B13: =INDEX('Trade Analysis'!$B$11:$B$14,MATCH(MAX('Trade Analysis'!$D$11:$D$14),'Trade Analysis'!$D$11:$D$14,0)) -> China | C13: Latest year, selected importers
A14: imports (EJ) | B14: =MAX('Trade Analysis'!$D$11:$D$14) -> 11.62
A15: share of world coal trade | B15: =INDEX('Trade Analysis'!$G$11:$G$14,MATCH(MAX('Trade Analysis'!$D$11:$D$14),'Trade Analysis'!$D$11:$D$14,0))/100 -> 0.323
A16: Largest exporter | B16: =INDEX('Trade Analysis'!$B$8:$B$10,MATCH(MAX('Trade Analysis'!$D$8:$D$10),'Trade Analysis'!$D$8:$D$10,0)) -> Indonesia | C16: Latest year, selected exporters
A17: exports (EJ) | B17: =MAX('Trade Analysis'!$D$8:$D$10) -> 10.72
A18: share of world coal trade | B18: =INDEX('Trade Analysis'!$G$8:$G$10,MATCH(MAX('Trade Analysis'!$D$8:$D$10),'Trade Analysis'!$D$8:$D$10,0))/100 -> 0.298
A19: Top two exporters, share of world trade (latest) | B19: ='Trade Analysis'!$G$19/100 -> 0.55 | C19: Countries reported in both years (like-for-like)
A20: Top two exporters, share of world trade (prior) | B20: ='Trade Analysis'!$G$18/100 -> 0.536 | C20: Same countries
A21: Benchmark price, latest year (USD/t) | B21: ='Price Analysis'!$B$16 -> 108.4 | C21: Australian thermal coal
A22: Benchmark price at peak (USD/t) | B22: ='Price Analysis'!$B$14 -> 344.9 | C22: Peak year in Price Analysis
A23: Latest price vs peak | B23: ='Price Analysis'!$B$17 -> -0.685706
A25: Key findings (narrative generated from the data when the workbook was built)
A26: Scale: China produced 4,780 Mt in 2024 (67% of the five selected markets) and consumed 92.2 EJ (73% of selected consumption).
A27: India: production grew 5.3% a year and consumption 4.8% a year over 2014-2024; consumption rose 14.7% in 2024 alone.
A28: Indonesia: production CAGR 6.2%, consumption CAGR 11.5%; includes a +59% jump in 2023 that needs source verification.
A29: Export dependence: Indonesia exported 10.72 EJ in 2024 (2.3x its domestic consumption); Australia exported 9.07 EJ (6.0x its domestic consumption).
A30: Import dependence (2024, imports / domestic consumption): Japan 96%, India 23%, China 13%.
A31: China's import pull: imports rose 14.4% to 11.62 EJ and its share of world trade moved +3.6 pp to 32.3%.
A32: Concentration: the two exporters present in both years (Australia, Indonesia) supplied 55.0% of world trade in 2024 vs 53.6% in 2023; the four listed importers took 67.6% (vs 65.2%).
A33: Price: Australian thermal coal averaged $345/t in 2022 (peak), $108/t in 2025 (-69% vs peak, -22% vs 2021).
A34: Contracting markets: Australia (production -0.9%, consumption -2.2% CAGR) and Japan (consumption -1.1% CAGR) are shrinking domestically.
A36: Where each business question is answered
A37: Which markets show sustained production and consumption growth? | B37: Market Trends
A38: Which importers represent the largest demand pools? | B38: Trade Analysis
A39: How concentrated is selected international coal trade? | B39: Trade Analysis (concentration table)
A40: How has benchmark thermal-coal pricing changed since the 2022 spike? | B40: Price Analysis
A41: Where do supply growth and demand growth diverge? | B41: Market Trends (growth gap and signal columns)
A42: Which data points should be verified before relying on conclusions? | B42: Data Quality
A44: These are historical observations from public data, not forecasts or investment recommendations.

Sheet Business Dashboard
A1: Business Dashboard
A2: All tiles and charts read from the analysis sheets and update when the data sheets change.
A4: Largest producer | D4: Largest producer share | G4: Largest importer | J4: Latest price vs peak
A5: ='Executive Summary'!$B$6 -> China | D5: ='Executive Summary'!$B$8 -> 0.66716914 | G5: ='Executive Summary'!$B$13 -> China | J5: ='Executive Summary'!$B$23 -> -0.685706
A41: Note: Russia has no 2024 export figure in the supplied data, so its 2024 bar is empty. Not a zero.

Sheet Market Trends
A1: Market Trends: supply and demand
A2: Production in Mt, consumption in EJ. Units differ, so supply and demand are compared through growth rates and indices, never subtracted.
A3: Base year | B3: 2014 | C3: <- yellow cells are assumptions you can change
A4: Recent window start | B4: 2019
A5: Latest year | B5: 2024
A6: Growth threshold (CAGR) | B6: 0.02
A8: Country | B8: Production base year (Mt) | C8: Production recent start (Mt) | D8: Production latest (Mt) | E8: Production CAGR (full period) | F8: Production CAGR (recent) | G8: Share of selected production | H8: Consumption base year (EJ) | I8: Consumption recent start (EJ) | J8: Consumption latest (EJ) | K8: Consumption CAGR (full period) | L8: Consumption CAGR (recent) | M8: Share of selected consumption | N8: Growth gap: production minus consumption CAGR (pp) | O8: Production rank | P8: Consumption rank | Q8: Market signal | R8: Production YoY, latest year | S8: Consumption YoY, latest year
A9: China | B9: =SUMIFS(Data_Market!$C$2:$C$500,Data_Market!$B$2:$B$500,$A9,Data_Market!$A$2:$A$500,$B$3) -> 3873.9 | C9: =SUMIFS(Data_Market!$C$2:$C$500,Data_Market!$B$2:$B$500,$A9,Data_Market!$A$2:$A$500,$B$4) -> 3846.3 | D9: =SUMIFS(Data_Market!$C$2:$C$500,Data_Market!$B$2:$B$500,$A9,Data_Market!$A$2:$A$500,$B$5) -> 4780 | E9: =IFERROR((D9/B9)^(1/($B$5-$B$3))-1,"n/a") -> 0.021240311 | F9: =IFERROR((D9/C9)^(1/($B$5-$B$4))-1,"n/a") -> 0.044424253 | G9: =D9/D$14 -> 0.66716914 | H9: =SUMIFS(Data_Market!$D$2:$D$500,Data_Market!$B$2:$B$500,$A9,Data_Market!$A$2:$A$500,$B$3) -> 82.45 | I9: =SUMIFS(Data_Market!$D$2:$D$500,Data_Market!$B$2:$B$500,$A9,Data_Market!$A$2:$A$500,$B$4) -> 80.47 | J9: =SUMIFS(Data_Market!$D$2:$D$500,Data_Market!$B$2:$B$500,$A9,Data_Market!$A$2:$A$500,$B$5) -> 92.16 | K9: =IFERROR((J9/H9)^(1/($B$5-$B$3))-1,"n/a") -> 0.011195622 | L9: =IFERROR((J9/I9)^(1/($B$5-$B$4))-1,"n/a") -> 0.027499674 | M9: =J9/J$14 -> 0.73200953 | N9: =IFERROR((E9-K9)*100,"n/a") -> 1.0044689 | O9: =RANK(D9,$D$9:$D$13) -> 1 | P9: =RANK(J9,$J$9:$J$13) -> 1 | Q9: =IF(AND(E9>$B$6,K9>$B$6),"Supply and demand growing",IF(AND(E9<0,K9<0),"Supply and demand contracting",IF(K9>$B$6,"Demand-led growth",IF(E9>$B$6,"Supply-led growth","Mixed / flat")))) -> Supply-led growth | R9: =IFERROR(INDEX(Data_Market!$C$2:$C$500,MATCH($A9&"|"&$B$5,Data_Market!$E$2:$E$500,0))/INDEX(Data_Market!$C$2:$C$500,MATCH($A9&"|"&($B$5-1),Data_Market!$E$2:$E$500,0))-1,"n/a") -> 0.012004319 | S9: =IFERROR(INDEX(Data_Market!$D$2:$D$500,MATCH($A9&"|"&$B$5,Data_Market!$E$2:$E$500,0))/INDEX(Data_Market!$D$2:$D$500,MATCH($A9&"|"&($B$5-1),Data_Market!$E$2:$E$500,0))-1,"n/a") -> 0.049299784
A10: India | B10: =SUMIFS(Data_Market!$C$2:$C$500,Data_Market!$B$2:$B$500,$A10,Data_Market!$A$2:$A$500,$B$3) -> 646.2 | C10: =SUMIFS(Data_Market!$C$2:$C$500,Data_Market!$B$2:$B$500,$A10,Data_Market!$A$2:$A$500,$B$4) -> 753.9 | D10: =SUMIFS(Data_Market!$C$2:$C$500,Data_Market!$B$2:$B$500,$A10,Data_Market!$A$2:$A$500,$B$5) -> 1085.1 | E10: =IFERROR((D10/B10)^(1/($B$5-$B$3))-1,"n/a") -> 0.053198619 | F10: =IFERROR((D10/C10)^(1/($B$5-$B$4))-1,"n/a") -> 0.075551485 | G10: =D10/D$14 -> 0.15145298 | H10: =SUMIFS(Data_Market!$D$2:$D$500,Data_Market!$B$2:$B$500,$A10,Data_Market!$A$2:$A$500,$B$3) -> 14.44 | I10: =SUMIFS(Data_Market!$D$2:$D$500,Data_Market!$B$2:$B$500,$A10,Data_Market!$A$2:$A$500,$B$4) -> 17.93 | J10: =SUMIFS(Data_Market!$D$2:$D$500,Data_Market!$B$2:$B$500,$A10,Data_Market!$A$2:$A$500,$B$5) -> 22.97 | K10: =IFERROR((J10/H10)^(1/($B$5-$B$3))-1,"n/a") -> 0.047512901 | L10: =IFERROR((J10/I10)^(1/($B$5-$B$4))-1,"n/a") -> 0.050790508 | M10: =J10/J$14 -> 0.18244639 | N10: =IFERROR((E10-K10)*100,"n/a") -> 0.56857185 | O10: =RANK(D10,$D$9:$D$13) -> 2 | P10: =RANK(J10,$J$9:$J$13) -> 2 | Q10: =IF(AND(E10>$B$6,K10>$B$6),"Supply and demand growing",IF(AND(E10<0,K10<0),"Supply and demand contracting",IF(K10>$B$6,"Demand-led growth",IF(E10>$B$6,"Supply-led growth","Mixed / flat")))) -> Supply and demand growing | R10: =IFERROR(INDEX(Data_Market!$C$2:$C$500,MATCH($A10&"|"&$B$5,Data_Market!$E$2:$E$500,0))/INDEX(Data_Market!$C$2:$C$500,MATCH($A10&"|"&($B$5-1),Data_Market!$E$2:$E$500,0))-1,"n/a") -> 0.072975378 | S10: =IFERROR(INDEX(Data_Market!$D$2:$D$500,MATCH($A10&"|"&$B$5,Data_Market!$E$2:$E$500,0))/INDEX(Data_Market!$D$2:$D$500,MATCH($A10&"|"&($B$5-1),Data_Market!$E$2:$E$500,0))-1,"n/a") -> 0.14677983
A11: Indonesia | B11: =SUMIFS(Data_Market!$C$2:$C$500,Data_Market!$B$2:$B$500,$A11,Data_Market!$A$2:$A$500,$B$3) -> 458.1 | C11: =SUMIFS(Data_Market!$C$2:$C$500,Data_Market!$B$2:$B$500,$A11,Data_Market!$A$2:$A$500,$B$4) -> 616.2 | D11: =SUMIFS(Data_Market!$C$2:$C$500,Data_Market!$B$2:$B$500,$A11,Data_Market!$A$2:$A$500,$B$5) -> 836.1 | E11: =IFERROR((D11/B11)^(1/($B$5-$B$3))-1,"n/a") -> 0.062012903 | F11: =IFERROR((D11/C11)^(1/($B$5-$B$4))-1,"n/a") -> 0.062936464 | G11: =D11/D$14 -> 0.11669877 | H11: =SUMIFS(Data_Market!$D$2:$D$500,Data_Market!$B$2:$B$500,$A11,Data_Market!$A$2:$A$500,$B$3) -> 1.59 | I11: =SUMIFS(Data_Market!$D$2:$D$500,Data_Market!$B$2:$B$500,$A11,Data_Market!$A$2:$A$500,$B$4) -> 2.36 | J11: =SUMIFS(Data_Market!$D$2:$D$500,Data_Market!$B$2:$B$500,$A11,Data_Market!$A$2:$A$500,$B$5) -> 4.72 | K11: =IFERROR((J11/H11)^(1/($B$5-$B$3))-1,"n/a") -> 0.11494768 | L11: =IFERROR((J11/I11)^(1/($B$5-$B$4))-1,"n/a") -> 0.14869835 | M11: =J11/J$14 -> 0.037490071 | N11: =IFERROR((E11-K11)*100,"n/a") -> -5.2934775 | O11: =RANK(D11,$D$9:$D$13) -> 3 | P11: =RANK(J11,$J$9:$J$13) -> 3 | Q11: =IF(AND(E11>$B$6,K11>$B$6),"Supply and demand growing",IF(AND(E11<0,K11<0),"Supply and demand contracting",IF(K11>$B$6,"Demand-led growth",IF(E11>$B$6,"Supply-led growth","Mixed / flat")))) -> Supply and demand growing | R11: =IFERROR(INDEX(Data_Market!$C$2:$C$500,MATCH($A11&"|"&$B$5,Data_Market!$E$2:$E$500,0))/INDEX(Data_Market!$C$2:$C$500,MATCH($A11&"|"&($B$5-1),Data_Market!$E$2:$E$500,0))-1,"n/a") -> 0.078560372 | S11: =IFERROR(INDEX(Data_Market!$D$2:$D$500,MATCH($A11&"|"&$B$5,Data_Market!$E$2:$E$500,0))/INDEX(Data_Market!$D$2:$D$500,MATCH($A11&"|"&($B$5-1),Data_Market!$E$2:$E$500,0))-1,"n/a") -> 0.077625571
A12: Australia | B12: =SUMIFS(Data_Market!$C$2:$C$500,Data_Market!$B$2:$B$500,$A12,Data_Market!$A$2:$A$500,$B$3) -> 505.3 | C12: =SUMIFS(Data_Market!$C$2:$C$500,Data_Market!$B$2:$B$500,$A12,Data_Market!$A$2:$A$500,$B$4) -> 505.4 | D12: =SUMIFS(Data_Market!$C$2:$C$500,Data_Market!$B$2:$B$500,$A12,Data_Market!$A$2:$A$500,$B$5) -> 462.9 | E12: =IFERROR((D12/B12)^(1/($B$5-$B$3))-1,"n/a") -> -0.0087258334 | F12: =IFERROR((D12/C12)^(1/($B$5-$B$4))-1,"n/a") -> -0.017414415 | G12: =D12/D$14 -> 0.064609329 | H12: =SUMIFS(Data_Market!$D$2:$D$500,Data_Market!$B$2:$B$500,$A12,Data_Market!$A$2:$A$500,$B$3) -> 1.89 | I12: =SUMIFS(Data_Market!$D$2:$D$500,Data_Market!$B$2:$B$500,$A12,Data_Market!$A$2:$A$500,$B$4) -> 1.83 | J12: =SUMIFS(Data_Market!$D$2:$D$500,Data_Market!$B$2:$B$500,$A12,Data_Market!$A$2:$A$500,$B$5) -> 1.52 | K12: =IFERROR((J12/H12)^(1/($B$5-$B$3))-1,"n/a") -> -0.021551035 | L12: =IFERROR((J12/I12)^(1/($B$5-$B$4))-1,"n/a") -> -0.036440584 | M12: =J12/J$14 -> 0.012073074 | N12: =IFERROR((E12-K12)*100,"n/a") -> 1.2825201 | O12: =RANK(D12,$D$9:$D$13) -> 4 | P12: =RANK(J12,$J$9:$J$13) -> 5 | Q12: =IF(AND(E12>$B$6,K12>$B$6),"Supply and demand growing",IF(AND(E12<0,K12<0),"Supply and demand contracting",IF(K12>$B$6,"Demand-led growth",IF(E12>$B$6,"Supply-led growth","Mixed / flat")))) -> Supply and demand contracting | R12: =IFERROR(INDEX(Data_Market!$C$2:$C$500,MATCH($A12&"|"&$B$5,Data_Market!$E$2:$E$500,0))/INDEX(Data_Market!$C$2:$C$500,MATCH($A12&"|"&($B$5-1),Data_Market!$E$2:$E$500,0))-1,"n/a") -> 0.0054300608 | S12: =IFERROR(INDEX(Data_Market!$D$2:$D$500,MATCH($A12&"|"&$B$5,Data_Market!$E$2:$E$500,0))/INDEX(Data_Market!$D$2:$D$500,MATCH($A12&"|"&($B$5-1),Data_Market!$E$2:$E$500,0))-1,"n/a") -> -0.012987013
A13: Japan | B13: =SUMIFS(Data_Market!$C$2:$C$500,Data_Market!$B$2:$B$500,$A13,Data_Market!$A$2:$A$500,$B$3) -> 1.3 | C13: =SUMIFS(Data_Market!$C$2:$C$500,Data_Market!$B$2:$B$500,$A13,Data_Market!$A$2:$A$500,$B$4) -> 0.8 | D13: =SUMIFS(Data_Market!$C$2:$C$500,Data_Market!$B$2:$B$500,$A13,Data_Market!$A$2:$A$500,$B$5) -> 0.5 | E13: =IFERROR((D13/B13)^(1/($B$5-$B$3))-1,"n/a") -> -0.091128123 | F13: =IFERROR((D13/C13)^(1/($B$5-$B$4))-1,"n/a") -> -0.089717898 | G13: =D13/D$14 -> 6.9787567e-05 | H13: =SUMIFS(Data_Market!$D$2:$D$500,Data_Market!$B$2:$B$500,$A13,Data_Market!$A$2:$A$500,$B$3) -> 5.07 | I13: =SUMIFS(Data_Market!$D$2:$D$500,Data_Market!$B$2:$B$500,$A13,Data_Market!$A$2:$A$500,$B$4) -> 4.99 | J13: =SUMIFS(Data_Market!$D$2:$D$500,Data_Market!$B$2:$B$500,$A13,Data_Market!$A$2:$A$500,$B$5) -> 4.53 | K13: =IFERROR((J13/H13)^(1/($B$5-$B$3))-1,"n/a") -> -0.01119871 | L13: =IFERROR((J13/I13)^(1/($B$5-$B$4))-1,"n/a") -> -0.019156923 | M13: =J13/J$14 -> 0.035980937 | N13: =IFERROR((E13-K13)*100,"n/a") -> -7.9929413 | O13: =RANK(D13,$D$9:$D$13) -> 5 | P13: =RANK(J13,$J$9:$J$13) -> 4 | Q13: =IF(AND(E13>$B$6,K13>$B$6),"Supply and demand growing",IF(AND(E13<0,K13<0),"Supply and demand contracting",IF(K13>$B$6,"Demand-led growth",IF(E13>$B$6,"Supply-led growth","Mixed / flat")))) -> Supply and demand contracting | R13: =IFERROR(INDEX(Data_Market!$C$2:$C$500,MATCH($A13&"|"&$B$5,Data_Market!$E$2:$E$500,0))/INDEX(Data_Market!$C$2:$C$500,MATCH($A13&"|"&($B$5-1),Data_Market!$E$2:$E$500,0))-1,"n/a") -> 0 | S13: =IFERROR(INDEX(Data_Market!$D$2:$D$500,MATCH($A13&"|"&$B$5,Data_Market!$E$2:$E$500,0))/INDEX(Data_Market!$D$2:$D$500,MATCH($A13&"|"&($B$5-1),Data_Market!$E$2:$E$500,0))-1,"n/a") -> -0.079268293
A14: Total (selected) | B14: =SUM(B9:B13) -> 5484.8 | C14: =SUM(C9:C13) -> 5722.6 | D14: =SUM(D9:D13) -> 7164.6 | E14: =IFERROR((D14/B14)^(1/($B$5-$B$3))-1,"n/a") -> 0.027077263 | F14: =IFERROR((D14/C14)^(1/($B$5-$B$4))-1,"n/a") -> 0.045971164 | G14: =SUM(G9:G13) -> 1 | H14: =SUM(H9:H13) -> 105.44 | I14: =SUM(I9:I13) -> 107.58 | J14: =SUM(J9:J13) -> 125.9 | K14: =IFERROR((J14/H14)^(1/($B$5-$B$3))-1,"n/a") -> 0.017892779 | L14: =IFERROR((J14/I14)^(1/($B$5-$B$4))-1,"n/a") -> 0.031950434 | M14: =SUM(M9:M13) -> 1
A15: Caution: Indonesia consumption jumped +59% in 2023 (see Data Quality) and Japan produces about 0.5 Mt, so their CAGRs are sensitive to a single data point. Red YoY = move above 40%.
A17: Production index (base year = 100) | H17: Consumption index (base year = 100)
A18: Year | B18: =$A$9 -> China | C18: =$A$10 -> India | D18: =$A$11 -> Indonesia | E18: =$A$12 -> Australia | F18: =$A$13 -> Japan | H18: Year | I18: =$A$9 -> China | J18: =$A$10 -> India | K18: =$A$11 -> Indonesia | L18: =$A$12 -> Australia | M18: =$A$13 -> Japan
A19: =$B$3 -> 2014 | B19: =SUMIFS(Data_Market!$C$2:$C$500,Data_Market!$B$2:$B$500,B$18,Data_Market!$A$2:$A$500,$A19)/SUMIFS(Data_Market!$C$2:$C$500,Data_Market!$B$2:$B$500,B$18,Data_Market!$A$2:$A$500,$B$3)*100 -> 100 | C19: =SUMIFS(Data_Market!$C$2:$C$500,Data_Market!$B$2:$B$500,C$18,Data_Market!$A$2:$A$500,$A19)/SUMIFS(Data_Market!$C$2:$C$500,Data_Market!$B$2:$B$500,C$18,Data_Market!$A$2:$A$500,$B$3)*100 -> 100 | D19: =SUMIFS(Data_Market!$C$2:$C$500,Data_Market!$B$2:$B$500,D$18,Data_Market!$A$2:$A$500,$A19)/SUMIFS(Data_Market!$C$2:$C$500,Data_Market!$B$2:$B$500,D$18,Data_Market!$A$2:$A$500,$B$3)*100 -> 100 | E19: =SUMIFS(Data_Market!$C$2:$C$500,Data_Market!$B$2:$B$500,E$18,Data_Market!$A$2:$A$500,$A19)/SUMIFS(Data_Market!$C$2:$C$500,Data_Market!$B$2:$B$500,E$18,Data_Market!$A$2:$A$500,$B$3)*100 -> 100 | F19: =SUMIFS(Data_Market!$C$2:$C$500,Data_Market!$B$2:$B$500,F$18,Data_Market!$A$2:$A$500,$A19)/SUMIFS(Data_Market!$C$2:$C$500,Data_Market!$B$2:$B$500,F$18,Data_Market!$A$2:$A$500,$B$3)*100 -> 100 | H19: =A19 -> 2014 | I19: =SUMIFS(Data_Market!$D$2:$D$500,Data_Market!$B$2:$B$500,I$18,Data_Market!$A$2:$A$500,$H19)/SUMIFS(Data_Market!$D$2:$D$500,Data_Market!$B$2:$B$500,I$18,Data_Market!$A$2:$A$500,$B$3)*100 -> 100 | J19: =SUMIFS(Data_Market!$D$2:$D$500,Data_Market!$B$2:$B$500,J$18,Data_Market!$A$2:$A$500,$H19)/SUMIFS(Data_Market!$D$2:$D$500,Data_Market!$B$2:$B$500,J$18,Data_Market!$A$2:$A$500,$B$3)*100 -> 100 | K19: =SUMIFS(Data_Market!$D$2:$D$500,Data_Market!$B$2:$B$500,K$18,Data_Market!$A$2:$A$500,$H19)/SUMIFS(Data_Market!$D$2:$D$500,Data_Market!$B$2:$B$500,K$18,Data_Market!$A$2:$A$500,$B$3)*100 -> 100 | L19: =SUMIFS(Data_Market!$D$2:$D$500,Data_Market!$B$2:$B$500,L$18,Data_Market!$A$2:$A$500,$H19)/SUMIFS(Data_Market!$D$2:$D$500,Data_Market!$B$2:$B$500,L$18,Data_Market!$A$2:$A$500,$B$3)*100 -> 100 | M19: =SUMIFS(Data_Market!$D$2:$D$500,Data_Market!$B$2:$B$500,M$18,Data_Market!$A$2:$A$500,$H19)/SUMIFS(Data_Market!$D$2:$D$500,Data_Market!$B$2:$B$500,M$18,Data_Market!$A$2:$A$500,$B$3)*100 -> 100
A20: =A19+1 -> 2015 | B20: =SUMIFS(Data_Market!$C$2:$C$500,Data_Market!$B$2:$B$500,B$18,Data_Market!$A$2:$A$500,$A20)/SUMIFS(Data_Market!$C$2:$C$500,Data_Market!$B$2:$B$500,B$18,Data_Market!$A$2:$A$500,$B$3)*100 -> 96.711325 | C20: =SUMIFS(Data_Market!$C$2:$C$500,Data_Market!$B$2:$B$500,C$18,Data_Market!$A$2:$A$500,$A20)/SUMIFS(Data_Market!$C$2:$C$500,Data_Market!$B$2:$B$500,C$18,Data_Market!$A$2:$A$500,$B$3)*100 -> 104.33302 | D20: =SUMIFS(Data_Market!$C$2:$C$500,Data_Market!$B$2:$B$500,D$18,Data_Market!$A$2:$A$500,$A20)/SUMIFS(Data_Market!$C$2:$C$500,Data_Market!$B$2:$B$500,D$18,Data_Market!$A$2:$A$500,$B$3)*100 -> 100.76403 | E20: =SUMIFS(Data_Market!$C$2:$C$500,Data_Market!$B$2:$B$500,E$18,Data_Market!$A$2:$A$500,$A20)/SUMIFS(Data_Market!$C$2:$C$500,Data_Market!$B$2:$B$500,E$18,Data_Market!$A$2:$A$500,$B$3)*100 -> 99.683356 | F20: =SUMIFS(Data_Market!$C$2:$C$500,Data_Market!$B$2:$B$500,F$18,Data_Market!$A$2:$A$500,$A20)/SUMIFS(Data_Market!$C$2:$C$500,Data_Market!$B$2:$B$500,F$18,Data_Market!$A$2:$A$500,$B$3)*100 -> 92.307692 | H20: =A20 -> 2015 | I20: =SUMIFS(Data_Market!$D$2:$D$500,Data_Market!$B$2:$B$500,I$18,Data_Market!$A$2:$A$500,$H20)/SUMIFS(Data_Market!$D$2:$D$500,Data_Market!$B$2:$B$500,I$18,Data_Market!$A$2:$A$500,$B$3)*100 -> 99.5755 | J20: =SUMIFS(Data_Market!$D$2:$D$500,Data_Market!$B$2:$B$500,J$18,Data_Market!$A$2:$A$500,$H20)/SUMIFS(Data_Market!$D$2:$D$500,Data_Market!$B$2:$B$500,J$18,Data_Market!$A$2:$A$500,$B$3)*100 -> 109.69529 | K20: =SUMIFS(Data_Market!$D$2:$D$500,Data_Market!$B$2:$B$500,K$18,Data_Market!$A$2:$A$500,$H20)/SUMIFS(Data_Market!$D$2:$D$500,Data_Market!$B$2:$B$500,K$18,Data_Market!$A$2:$A$500,$B$3)*100 -> 106.28931 | L20: =SUMIFS(Data_Market!$D$2:$D$500,Data_Market!$B$2:$B$500,L$18,Data_Market!$A$2:$A$500,$H20)/SUMIFS(Data_Market!$D$2:$D$500,Data_Market!$B$2:$B$500,L$18,Data_Market!$A$2:$A$500,$B$3)*100 -> 99.470899 | M20: =SUMIFS(Data_Market!$D$2:$D$500,Data_Market!$B$2:$B$500,M$18,Data_Market!$A$2:$A$500,$H20)/SUMIFS(Data_Market!$D$2:$D$500,Data_Market!$B$2:$B$500,M$18,Data_Market!$A$2:$A$500,$B$3)*100 -> 98.422091
A21: =A20+1 -> 2016 | B21: =SUMIFS(Data_Market!$C$2:$C$500,Data_Market!$B$2:$B$500,B$18,Data_Market!$A$2:$A$500,$A21)/SUMIFS(Data_Market!$C$2:$C$500,Data_Market!$B$2:$B$500,B$18,Data_Market!$A$2:$A$500,$B$3)*100 -> 88.040476 | C21: =SUMIFS(Data_Market!$C$2:$C$500,Data_Market!$B$2:$B$500,C$18,Data_Market!$A$2:$A$500,$A21)/SUMIFS(Data_Market!$C$2:$C$500,Data_Market!$B$2:$B$500,C$18,Data_Market!$A$2:$A$500,$B$3)*100 -> 106.74714 | D21: =SUMIFS(Data_Market!$C$2:$C$500,Data_Market!$B$2:$B$500,D$18,Data_Market!$A$2:$A$500,$A21)/SUMIFS(Data_Market!$C$2:$C$500,Data_Market!$B$2:$B$500,D$18,Data_Market!$A$2:$A$500,$B$3)*100 -> 100.67671 | E21: =SUMIFS(Data_Market!$C$2:$C$500,Data_Market!$B$2:$B$500,E$18,Data_Market!$A$2:$A$500,$A21)/SUMIFS(Data_Market!$C$2:$C$500,Data_Market!$B$2:$B$500,E$18,Data_Market!$A$2:$A$500,$B$3)*100 -> 99.366713 | F21: =SUMIFS(Data_Market!$C$2:$C$500,Data_Market!$B$2:$B$500,F$18,Data_Market!$A$2:$A$500,$A21)/SUMIFS(Data_Market!$C$2:$C$500,Data_Market!$B$2:$B$500,F$18,Data_Market!$A$2:$A$500,$B$3)*100 -> 100 | H21: =A21 -> 2016 | I21: =SUMIFS(Data_Market!$D$2:$D$500,Data_Market!$B$2:$B$500,I$18,Data_Market!$A$2:$A$500,$H21)/SUMIFS(Data_Market!$D$2:$D$500,Data_Market!$B$2:$B$500,I$18,Data_Market!$A$2:$A$500,$B$3)*100 -> 97.489388 | J21: =SUMIFS(Data_Market!$D$2:$D$500,Data_Market!$B$2:$B$500,J$18,Data_Market!$A$2:$A$500,$H21)/SUMIFS(Data_Market!$D$2:$D$500,Data_Market!$B$2:$B$500,J$18,Data_Market!$A$2:$A$500,$B$3)*100 -> 111.98061 | K21: =SUMIFS(Data_Market!$D$2:$D$500,Data_Market!$B$2:$B$500,K$18,Data_Market!$A$2:$A$500,$H21)/SUMIFS(Data_Market!$D$2:$D$500,Data_Market!$B$2:$B$500,K$18,Data_Market!$A$2:$A$500,$B$3)*100 -> 120.75472 | L21: =SUMIFS(Data_Market!$D$2:$D$500,Data_Market!$B$2:$B$500,L$18,Data_Market!$A$2:$A$500,$H21)/SUMIFS(Data_Market!$D$2:$D$500,Data_Market!$B$2:$B$500,L$18,Data_Market!$A$2:$A$500,$B$3)*100 -> 103.1746 | M21: =SUMIFS(Data_Market!$D$2:$D$500,Data_Market!$B$2:$B$500,M$18,Data_Market!$A$2:$A$500,$H21)/SUMIFS(Data_Market!$D$2:$D$500,Data_Market!$B$2:$B$500,M$18,Data_Market!$A$2:$A$500,$B$3)*100 -> 99.211045
A22: =A21+1 -> 2017 | B22: =SUMIFS(Data_Market!$C$2:$C$500,Data_Market!$B$2:$B$500,B$18,Data_Market!$A$2:$A$500,$A22)/SUMIFS(Data_Market!$C$2:$C$500,Data_Market!$B$2:$B$500,B$18,Data_Market!$A$2:$A$500,$B$3)*100 -> 90.957433 | C22: =SUMIFS(Data_Market!$C$2:$C$500,Data_Market!$B$2:$B$500,C$18,Data_Market!$A$2:$A$500,$A22)/SUMIFS(Data_Market!$C$2:$C$500,Data_Market!$B$2:$B$500,C$18,Data_Market!$A$2:$A$500,$B$3)*100 -> 110.13618 | D22: =SUMIFS(Data_Market!$C$2:$C$500,Data_Market!$B$2:$B$500,D$18,Data_Market!$A$2:$A$500,$A22)/SUMIFS(Data_Market!$C$2:$C$500,Data_Market!$B$2:$B$500,D$18,Data_Market!$A$2:$A$500,$B$3)*100 -> 100.67671 | E22: =SUMIFS(Data_Market!$C$2:$C$500,Data_Market!$B$2:$B$500,E$18,Data_Market!$A$2:$A$500,$A22)/SUMIFS(Data_Market!$C$2:$C$500,Data_Market!$B$2:$B$500,E$18,Data_Market!$A$2:$A$500,$B$3)*100 -> 96.41797 | F22: =SUMIFS(Data_Market!$C$2:$C$500,Data_Market!$B$2:$B$500,F$18,Data_Market!$A$2:$A$500,$A22)/SUMIFS(Data_Market!$C$2:$C$500,Data_Market!$B$2:$B$500,F$18,Data_Market!$A$2:$A$500,$B$3)*100 -> 107.69231 | H22: =A22 -> 2017 | I22: =SUMIFS(Data_Market!$D$2:$D$500,Data_Market!$B$2:$B$500,I$18,Data_Market!$A$2:$A$500,$H22)/SUMIFS(Data_Market!$D$2:$D$500,Data_Market!$B$2:$B$500,I$18,Data_Market!$A$2:$A$500,$B$3)*100 -> 94.639175 | J22: =SUMIFS(Data_Market!$D$2:$D$500,Data_Market!$B$2:$B$500,J$18,Data_Market!$A$2:$A$500,$H22)/SUMIFS(Data_Market!$D$2:$D$500,Data_Market!$B$2:$B$500,J$18,Data_Market!$A$2:$A$500,$B$3)*100 -> 114.40443 | K22: =SUMIFS(Data_Market!$D$2:$D$500,Data_Market!$B$2:$B$500,K$18,Data_Market!$A$2:$A$500,$H22)/SUMIFS(Data_Market!$D$2:$D$500,Data_Market!$B$2:$B$500,K$18,Data_Market!$A$2:$A$500,$B$3)*100 -> 123.27044 | L22: =SUMIFS(Data_Market!$D$2:$D$500,Data_Market!$B$2:$B$500,L$18,Data_Market!$A$2:$A$500,$H22)/SUMIFS(Data_Market!$D$2:$D$500,Data_Market!$B$2:$B$500,L$18,Data_Market!$A$2:$A$500,$B$3)*100 -> 102.6455 | M22: =SUMIFS(Data_Market!$D$2:$D$500,Data_Market!$B$2:$B$500,M$18,Data_Market!$A$2:$A$500,$H22)/SUMIFS(Data_Market!$D$2:$D$500,Data_Market!$B$2:$B$500,M$18,Data_Market!$A$2:$A$500,$B$3)*100 -> 99.013807
A23: =A22+1 -> 2018 | B23: =SUMIFS(Data_Market!$C$2:$C$500,Data_Market!$B$2:$B$500,B$18,Data_Market!$A$2:$A$500,$A23)/SUMIFS(Data_Market!$C$2:$C$500,Data_Market!$B$2:$B$500,B$18,Data_Market!$A$2:$A$500,$B$3)*100 -> 95.451612 | C23: =SUMIFS(Data_Market!$C$2:$C$500,Data_Market!$B$2:$B$500,C$18,Data_Market!$A$2:$A$500,$A23)/SUMIFS(Data_Market!$C$2:$C$500,Data_Market!$B$2:$B$500,C$18,Data_Market!$A$2:$A$500,$B$3)*100 -> 117.67255 | D23: =SUMIFS(Data_Market!$C$2:$C$500,Data_Market!$B$2:$B$500,D$18,Data_Market!$A$2:$A$500,$A23)/SUMIFS(Data_Market!$C$2:$C$500,Data_Market!$B$2:$B$500,D$18,Data_Market!$A$2:$A$500,$B$3)*100 -> 121.76381 | E23: =SUMIFS(Data_Market!$C$2:$C$500,Data_Market!$B$2:$B$500,E$18,Data_Market!$A$2:$A$500,$A23)/SUMIFS(Data_Market!$C$2:$C$500,Data_Market!$B$2:$B$500,E$18,Data_Market!$A$2:$A$500,$B$3)*100 -> 99.346923 | F23: =SUMIFS(Data_Market!$C$2:$C$500,Data_Market!$B$2:$B$500,F$18,Data_Market!$A$2:$A$500,$A23)/SUMIFS(Data_Market!$C$2:$C$500,Data_Market!$B$2:$B$500,F$18,Data_Market!$A$2:$A$500,$B$3)*100 -> 76.923077 | H23: =A23 -> 2018 | I23: =SUMIFS(Data_Market!$D$2:$D$500,Data_Market!$B$2:$B$500,I$18,Data_Market!$A$2:$A$500,$H23)/SUMIFS(Data_Market!$D$2:$D$500,Data_Market!$B$2:$B$500,I$18,Data_Market!$A$2:$A$500,$B$3)*100 -> 95.69436 | J23: =SUMIFS(Data_Market!$D$2:$D$500,Data_Market!$B$2:$B$500,J$18,Data_Market!$A$2:$A$500,$H23)/SUMIFS(Data_Market!$D$2:$D$500,Data_Market!$B$2:$B$500,J$18,Data_Market!$A$2:$A$500,$B$3)*100 -> 118.07479 | K23: =SUMIFS(Data_Market!$D$2:$D$500,Data_Market!$B$2:$B$500,K$18,Data_Market!$A$2:$A$500,$H23)/SUMIFS(Data_Market!$D$2:$D$500,Data_Market!$B$2:$B$500,K$18,Data_Market!$A$2:$A$500,$B$3)*100 -> 128.30189 | L23: =SUMIFS(Data_Market!$D$2:$D$500,Data_Market!$B$2:$B$500,L$18,Data_Market!$A$2:$A$500,$H23)/SUMIFS(Data_Market!$D$2:$D$500,Data_Market!$B$2:$B$500,L$18,Data_Market!$A$2:$A$500,$B$3)*100 -> 99.470899 | M23: =SUMIFS(Data_Market!$D$2:$D$500,Data_Market!$B$2:$B$500,M$18,Data_Market!$A$2:$A$500,$H23)/SUMIFS(Data_Market!$D$2:$D$500,Data_Market!$B$2:$B$500,M$18,Data_Market!$A$2:$A$500,$B$3)*100 -> 100.59172
A24: =A23+1 -> 2019 | B24: =SUMIFS(Data_Market!$C$2:$C$500,Data_Market!$B$2:$B$500,B$18,Data_Market!$A$2:$A$500,$A24)/SUMIFS(Data_Market!$C$2:$C$500,Data_Market!$B$2:$B$500,B$18,Data_Market!$A$2:$A$500,$B$3)*100 -> 99.28754 | C24: =SUMIFS(Data_Market!$C$2:$C$500,Data_Market!$B$2:$B$500,C$18,Data_Market!$A$2:$A$500,$A24)/SUMIFS(Data_Market!$C$2:$C$500,Data_Market!$B$2:$B$500,C$18,Data_Market!$A$2:$A$500,$B$3)*100 -> 116.66667 | D24: =SUMIFS(Data_Market!$C$2:$C$500,Data_Market!$B$2:$B$500,D$18,Data_Market!$A$2:$A$500,$A24)/SUMIFS(Data_Market!$C$2:$C$500,Data_Market!$B$2:$B$500,D$18,Data_Market!$A$2:$A$500,$B$3)*100 -> 134.51212 | E24: =SUMIFS(Data_Market!$C$2:$C$500,Data_Market!$B$2:$B$500,E$18,Data_Market!$A$2:$A$500,$A24)/SUMIFS(Data_Market!$C$2:$C$500,Data_Market!$B$2:$B$500,E$18,Data_Market!$A$2:$A$500,$B$3)*100 -> 100.01979 | F24: =SUMIFS(Data_Market!$C$2:$C$500,Data_Market!$B$2:$B$500,F$18,Data_Market!$A$2:$A$500,$A24)/SUMIFS(Data_Market!$C$2:$C$500,Data_Market!$B$2:$B$500,F$18,Data_Market!$A$2:$A$500,$B$3)*100 -> 61.538462 | H24: =A24 -> 2019 | I24: =SUMIFS(Data_Market!$D$2:$D$500,Data_Market!$B$2:$B$500,I$18,Data_Market!$A$2:$A$500,$H24)/SUMIFS(Data_Market!$D$2:$D$500,Data_Market!$B$2:$B$500,I$18,Data_Market!$A$2:$A$500,$B$3)*100 -> 97.598545 | J24: =SUMIFS(Data_Market!$D$2:$D$500,Data_Market!$B$2:$B$500,J$18,Data_Market!$A$2:$A$500,$H24)/SUMIFS(Data_Market!$D$2:$D$500,Data_Market!$B$2:$B$500,J$18,Data_Market!$A$2:$A$500,$B$3)*100 -> 124.16898 | K24: =SUMIFS(Data_Market!$D$2:$D$500,Data_Market!$B$2:$B$500,K$18,Data_Market!$A$2:$A$500,$H24)/SUMIFS(Data_Market!$D$2:$D$500,Data_Market!$B$2:$B$500,K$18,Data_Market!$A$2:$A$500,$B$3)*100 -> 148.42767 | L24: =SUMIFS(Data_Market!$D$2:$D$500,Data_Market!$B$2:$B$500,L$18,Data_Market!$A$2:$A$500,$H24)/SUMIFS(Data_Market!$D$2:$D$500,Data_Market!$B$2:$B$500,L$18,Data_Market!$A$2:$A$500,$B$3)*100 -> 96.825397 | M24: =SUMIFS(Data_Market!$D$2:$D$500,Data_Market!$B$2:$B$500,M$18,Data_Market!$A$2:$A$500,$H24)/SUMIFS(Data_Market!$D$2:$D$500,Data_Market!$B$2:$B$500,M$18,Data_Market!$A$2:$A$500,$B$3)*100 -> 98.422091
A25: =A24+1 -> 2020 | B25: =SUMIFS(Data_Market!$C$2:$C$500,Data_Market!$B$2:$B$500,B$18,Data_Market!$A$2:$A$500,$A25)/SUMIFS(Data_Market!$C$2:$C$500,Data_Market!$B$2:$B$500,B$18,Data_Market!$A$2:$A$500,$B$3)*100 -> 100.71504 | C25: =SUMIFS(Data_Market!$C$2:$C$500,Data_Market!$B$2:$B$500,C$18,Data_Market!$A$2:$A$500,$A25)/SUMIFS(Data_Market!$C$2:$C$500,Data_Market!$B$2:$B$500,C$18,Data_Market!$A$2:$A$500,$B$3)*100 -> 117.6416 | D25: =SUMIFS(Data_Market!$C$2:$C$500,Data_Market!$B$2:$B$500,D$18,Data_Market!$A$2:$A$500,$A25)/SUMIFS(Data_Market!$C$2:$C$500,Data_Market!$B$2:$B$500,D$18,Data_Market!$A$2:$A$500,$B$3)*100 -> 123.05174 | E25: =SUMIFS(Data_Market!$C$2:$C$500,Data_Market!$B$2:$B$500,E$18,Data_Market!$A$2:$A$500,$A25)/SUMIFS(Data_Market!$C$2:$C$500,Data_Market!$B$2:$B$500,E$18,Data_Market!$A$2:$A$500,$B$3)*100 -> 92.598456 | F25: =SUMIFS(Data_Market!$C$2:$C$500,Data_Market!$B$2:$B$500,F$18,Data_Market!$A$2:$A$500,$A25)/SUMIFS(Data_Market!$C$2:$C$500,Data_Market!$B$2:$B$500,F$18,Data_Market!$A$2:$A$500,$B$3)*100 -> 61.538462 | H25: =A25 -> 2020 | I25: =SUMIFS(Data_Market!$D$2:$D$500,Data_Market!$B$2:$B$500,I$18,Data_Market!$A$2:$A$500,$H25)/SUMIFS(Data_Market!$D$2:$D$500,Data_Market!$B$2:$B$500,I$18,Data_Market!$A$2:$A$500,$B$3)*100 -> 100.0849 | J25: =SUMIFS(Data_Market!$D$2:$D$500,Data_Market!$B$2:$B$500,J$18,Data_Market!$A$2:$A$500,$H25)/SUMIFS(Data_Market!$D$2:$D$500,Data_Market!$B$2:$B$500,J$18,Data_Market!$A$2:$A$500,$B$3)*100 -> 124.37673 | K25: =SUMIFS(Data_Market!$D$2:$D$500,Data_Market!$B$2:$B$500,K$18,Data_Market!$A$2:$A$500,$H25)/SUMIFS(Data_Market!$D$2:$D$500,Data_Market!$B$2:$B$500,K$18,Data_Market!$A$2:$A$500,$B$3)*100 -> 181.13208 | L25: =SUMIFS(Data_Market!$D$2:$D$500,Data_Market!$B$2:$B$500,L$18,Data_Market!$A$2:$A$500,$H25)/SUMIFS(Data_Market!$D$2:$D$500,Data_Market!$B$2:$B$500,L$18,Data_Market!$A$2:$A$500,$B$3)*100 -> 92.592593 | M25: =SUMIFS(Data_Market!$D$2:$D$500,Data_Market!$B$2:$B$500,M$18,Data_Market!$A$2:$A$500,$H25)/SUMIFS(Data_Market!$D$2:$D$500,Data_Market!$B$2:$B$500,M$18,Data_Market!$A$2:$A$500,$B$3)*100 -> 96.844181
A26: =A25+1 -> 2021 | B26: =SUMIFS(Data_Market!$C$2:$C$500,Data_Market!$B$2:$B$500,B$18,Data_Market!$A$2:$A$500,$A26)/SUMIFS(Data_Market!$C$2:$C$500,Data_Market!$B$2:$B$500,B$18,Data_Market!$A$2:$A$500,$B$3)*100 -> 106.50249 | C26: =SUMIFS(Data_Market!$C$2:$C$500,Data_Market!$B$2:$B$500,C$18,Data_Market!$A$2:$A$500,$A26)/SUMIFS(Data_Market!$C$2:$C$500,Data_Market!$B$2:$B$500,C$18,Data_Market!$A$2:$A$500,$B$3)*100 -> 125.67317 | D26: =SUMIFS(Data_Market!$C$2:$C$500,Data_Market!$B$2:$B$500,D$18,Data_Market!$A$2:$A$500,$A26)/SUMIFS(Data_Market!$C$2:$C$500,Data_Market!$B$2:$B$500,D$18,Data_Market!$A$2:$A$500,$B$3)*100 -> 134.03187 | E26: =SUMIFS(Data_Market!$C$2:$C$500,Data_Market!$B$2:$B$500,E$18,Data_Market!$A$2:$A$500,$A26)/SUMIFS(Data_Market!$C$2:$C$500,Data_Market!$B$2:$B$500,E$18,Data_Market!$A$2:$A$500,$B$3)*100 -> 94.755591 | F26: =SUMIFS(Data_Market!$C$2:$C$500,Data_Market!$B$2:$B$500,F$18,Data_Market!$A$2:$A$500,$A26)/SUMIFS(Data_Market!$C$2:$C$500,Data_Market!$B$2:$B$500,F$18,Data_Market!$A$2:$A$500,$B$3)*100 -> 53.846154 | H26: =A26 -> 2021 | I26: =SUMIFS(Data_Market!$D$2:$D$500,Data_Market!$B$2:$B$500,I$18,Data_Market!$A$2:$A$500,$H26)/SUMIFS(Data_Market!$D$2:$D$500,Data_Market!$B$2:$B$500,I$18,Data_Market!$A$2:$A$500,$B$3)*100 -> 102.18314 | J26: =SUMIFS(Data_Market!$D$2:$D$500,Data_Market!$B$2:$B$500,J$18,Data_Market!$A$2:$A$500,$H26)/SUMIFS(Data_Market!$D$2:$D$500,Data_Market!$B$2:$B$500,J$18,Data_Market!$A$2:$A$500,$B$3)*100 -> 117.52078 | K26: =SUMIFS(Data_Market!$D$2:$D$500,Data_Market!$B$2:$B$500,K$18,Data_Market!$A$2:$A$500,$H26)/SUMIFS(Data_Market!$D$2:$D$500,Data_Market!$B$2:$B$500,K$18,Data_Market!$A$2:$A$500,$B$3)*100 -> 173.58491 | L26: =SUMIFS(Data_Market!$D$2:$D$500,Data_Market!$B$2:$B$500,L$18,Data_Market!$A$2:$A$500,$H26)/SUMIFS(Data_Market!$D$2:$D$500,Data_Market!$B$2:$B$500,L$18,Data_Market!$A$2:$A$500,$B$3)*100 -> 89.417989 | M26: =SUMIFS(Data_Market!$D$2:$D$500,Data_Market!$B$2:$B$500,M$18,Data_Market!$A$2:$A$500,$H26)/SUMIFS(Data_Market!$D$2:$D$500,Data_Market!$B$2:$B$500,M$18,Data_Market!$A$2:$A$500,$B$3)*100 -> 90.138067
A27: =A26+1 -> 2022 | B27: =SUMIFS(Data_Market!$C$2:$C$500,Data_Market!$B$2:$B$500,B$18,Data_Market!$A$2:$A$500,$A27)/SUMIFS(Data_Market!$C$2:$C$500,Data_Market!$B$2:$B$500,B$18,Data_Market!$A$2:$A$500,$B$3)*100 -> 117.67469 | C27: =SUMIFS(Data_Market!$C$2:$C$500,Data_Market!$B$2:$B$500,C$18,Data_Market!$A$2:$A$500,$A27)/SUMIFS(Data_Market!$C$2:$C$500,Data_Market!$B$2:$B$500,C$18,Data_Market!$A$2:$A$500,$B$3)*100 -> 140.94708 | D27: =SUMIFS(Data_Market!$C$2:$C$500,Data_Market!$B$2:$B$500,D$18,Data_Market!$A$2:$A$500,$A27)/SUMIFS(Data_Market!$C$2:$C$500,Data_Market!$B$2:$B$500,D$18,Data_Market!$A$2:$A$500,$B$3)*100 -> 150.05457 | E27: =SUMIFS(Data_Market!$C$2:$C$500,Data_Market!$B$2:$B$500,E$18,Data_Market!$A$2:$A$500,$A27)/SUMIFS(Data_Market!$C$2:$C$500,Data_Market!$B$2:$B$500,E$18,Data_Market!$A$2:$A$500,$B$3)*100 -> 90.738175 | F27: =SUMIFS(Data_Market!$C$2:$C$500,Data_Market!$B$2:$B$500,F$18,Data_Market!$A$2:$A$500,$A27)/SUMIFS(Data_Market!$C$2:$C$500,Data_Market!$B$2:$B$500,F$18,Data_Market!$A$2:$A$500,$B$3)*100 -> 53.846154 | H27: =A27 -> 2022 | I27: =SUMIFS(Data_Market!$D$2:$D$500,Data_Market!$B$2:$B$500,I$18,Data_Market!$A$2:$A$500,$H27)/SUMIFS(Data_Market!$D$2:$D$500,Data_Market!$B$2:$B$500,I$18,Data_Market!$A$2:$A$500,$B$3)*100 -> 106.17344 | J27: =SUMIFS(Data_Market!$D$2:$D$500,Data_Market!$B$2:$B$500,J$18,Data_Market!$A$2:$A$500,$H27)/SUMIFS(Data_Market!$D$2:$D$500,Data_Market!$B$2:$B$500,J$18,Data_Market!$A$2:$A$500,$B$3)*100 -> 133.44875 | K27: =SUMIFS(Data_Market!$D$2:$D$500,Data_Market!$B$2:$B$500,K$18,Data_Market!$A$2:$A$500,$H27)/SUMIFS(Data_Market!$D$2:$D$500,Data_Market!$B$2:$B$500,K$18,Data_Market!$A$2:$A$500,$B$3)*100 -> 172.95597 | L27: =SUMIFS(Data_Market!$D$2:$D$500,Data_Market!$B$2:$B$500,L$18,Data_Market!$A$2:$A$500,$H27)/SUMIFS(Data_Market!$D$2:$D$500,Data_Market!$B$2:$B$500,L$18,Data_Market!$A$2:$A$500,$B$3)*100 -> 86.243386 | M27: =SUMIFS(Data_Market!$D$2:$D$500,Data_Market!$B$2:$B$500,M$18,Data_Market!$A$2:$A$500,$H27)/SUMIFS(Data_Market!$D$2:$D$500,Data_Market!$B$2:$B$500,M$18,Data_Market!$A$2:$A$500,$B$3)*100 -> 97.238659
A28: =A27+1 -> 2023 | B28: =SUMIFS(Data_Market!$C$2:$C$500,Data_Market!$B$2:$B$500,B$18,Data_Market!$A$2:$A$500,$A28)/SUMIFS(Data_Market!$C$2:$C$500,Data_Market!$B$2:$B$500,B$18,Data_Market!$A$2:$A$500,$B$3)*100 -> 121.92622 | C28: =SUMIFS(Data_Market!$C$2:$C$500,Data_Market!$B$2:$B$500,C$18,Data_Market!$A$2:$A$500,$A28)/SUMIFS(Data_Market!$C$2:$C$500,Data_Market!$B$2:$B$500,C$18,Data_Market!$A$2:$A$500,$B$3)*100 -> 156.49954 | D28: =SUMIFS(Data_Market!$C$2:$C$500,Data_Market!$B$2:$B$500,D$18,Data_Market!$A$2:$A$500,$A28)/SUMIFS(Data_Market!$C$2:$C$500,Data_Market!$B$2:$B$500,D$18,Data_Market!$A$2:$A$500,$B$3)*100 -> 169.22069 | E28: =SUMIFS(Data_Market!$C$2:$C$500,Data_Market!$B$2:$B$500,E$18,Data_Market!$A$2:$A$500,$A28)/SUMIFS(Data_Market!$C$2:$C$500,Data_Market!$B$2:$B$500,E$18,Data_Market!$A$2:$A$500,$B$3)*100 -> 91.11419 | F28: =SUMIFS(Data_Market!$C$2:$C$500,Data_Market!$B$2:$B$500,F$18,Data_Market!$A$2:$A$500,$A28)/SUMIFS(Data_Market!$C$2:$C$500,Data_Market!$B$2:$B$500,F$18,Data_Market!$A$2:$A$500,$B$3)*100 -> 38.461538 | H28: =A28 -> 2023 | I28: =SUMIFS(Data_Market!$D$2:$D$500,Data_Market!$B$2:$B$500,I$18,Data_Market!$A$2:$A$500,$H28)/SUMIFS(Data_Market!$D$2:$D$500,Data_Market!$B$2:$B$500,I$18,Data_Market!$A$2:$A$500,$B$3)*100 -> 106.52517 | J28: =SUMIFS(Data_Market!$D$2:$D$500,Data_Market!$B$2:$B$500,J$18,Data_Market!$A$2:$A$500,$H28)/SUMIFS(Data_Market!$D$2:$D$500,Data_Market!$B$2:$B$500,J$18,Data_Market!$A$2:$A$500,$B$3)*100 -> 138.71191 | K28: =SUMIFS(Data_Market!$D$2:$D$500,Data_Market!$B$2:$B$500,K$18,Data_Market!$A$2:$A$500,$H28)/SUMIFS(Data_Market!$D$2:$D$500,Data_Market!$B$2:$B$500,K$18,Data_Market!$A$2:$A$500,$B$3)*100 -> 275.4717 | L28: =SUMIFS(Data_Market!$D$2:$D$500,Data_Market!$B$2:$B$500,L$18,Data_Market!$A$2:$A$500,$H28)/SUMIFS(Data_Market!$D$2:$D$500,Data_Market!$B$2:$B$500,L$18,Data_Market!$A$2:$A$500,$B$3)*100 -> 81.481481 | M28: =SUMIFS(Data_Market!$D$2:$D$500,Data_Market!$B$2:$B$500,M$18,Data_Market!$A$2:$A$500,$H28)/SUMIFS(Data_Market!$D$2:$D$500,Data_Market!$B$2:$B$500,M$18,Data_Market!$A$2:$A$500,$B$3)*100 -> 97.04142
A29: =A28+1 -> 2024 | B29: =SUMIFS(Data_Market!$C$2:$C$500,Data_Market!$B$2:$B$500,B$18,Data_Market!$A$2:$A$500,$A29)/SUMIFS(Data_Market!$C$2:$C$500,Data_Market!$B$2:$B$500,B$18,Data_Market!$A$2:$A$500,$B$3)*100 -> 123.38987 | C29: =SUMIFS(Data_Market!$C$2:$C$500,Data_Market!$B$2:$B$500,C$18,Data_Market!$A$2:$A$500,$A29)/SUMIFS(Data_Market!$C$2:$C$500,Data_Market!$B$2:$B$500,C$18,Data_Market!$A$2:$A$500,$B$3)*100 -> 167.92015 | D29: =SUMIFS(Data_Market!$C$2:$C$500,Data_Market!$B$2:$B$500,D$18,Data_Market!$A$2:$A$500,$A29)/SUMIFS(Data_Market!$C$2:$C$500,Data_Market!$B$2:$B$500,D$18,Data_Market!$A$2:$A$500,$B$3)*100 -> 182.51473 | E29: =SUMIFS(Data_Market!$C$2:$C$500,Data_Market!$B$2:$B$500,E$18,Data_Market!$A$2:$A$500,$A29)/SUMIFS(Data_Market!$C$2:$C$500,Data_Market!$B$2:$B$500,E$18,Data_Market!$A$2:$A$500,$B$3)*100 -> 91.608945 | F29: =SUMIFS(Data_Market!$C$2:$C$500,Data_Market!$B$2:$B$500,F$18,Data_Market!$A$2:$A$500,$A29)/SUMIFS(Data_Market!$C$2:$C$500,Data_Market!$B$2:$B$500,F$18,Data_Market!$A$2:$A$500,$B$3)*100 -> 38.461538 | H29: =A29 -> 2024 | I29: =SUMIFS(Data_Market!$D$2:$D$500,Data_Market!$B$2:$B$500,I$18,Data_Market!$A$2:$A$500,$H29)/SUMIFS(Data_Market!$D$2:$D$500,Data_Market!$B$2:$B$500,I$18,Data_Market!$A$2:$A$500,$B$3)*100 -> 111.77683 | J29: =SUMIFS(Data_Market!$D$2:$D$500,Data_Market!$B$2:$B$500,J$18,Data_Market!$A$2:$A$500,$H29)/SUMIFS(Data_Market!$D$2:$D$500,Data_Market!$B$2:$B$500,J$18,Data_Market!$A$2:$A$500,$B$3)*100 -> 159.07202 | K29: =SUMIFS(Data_Market!$D$2:$D$500,Data_Market!$B$2:$B$500,K$18,Data_Market!$A$2:$A$500,$H29)/SUMIFS(Data_Market!$D$2:$D$500,Data_Market!$B$2:$B$500,K$18,Data_Market!$A$2:$A$500,$B$3)*100 -> 296.85535 | L29: =SUMIFS(Data_Market!$D$2:$D$500,Data_Market!$B$2:$B$500,L$18,Data_Market!$A$2:$A$500,$H29)/SUMIFS(Data_Market!$D$2:$D$500,Data_Market!$B$2:$B$500,L$18,Data_Market!$A$2:$A$500,$B$3)*100 -> 80.42328 | M29: =SUMIFS(Data_Market!$D$2:$D$500,Data_Market!$B$2:$B$500,M$18,Data_Market!$A$2:$A$500,$H29)/SUMIFS(Data_Market!$D$2:$D$500,Data_Market!$B$2:$B$500,M$18,Data_Market!$A$2:$A$500,$B$3)*100 -> 89.349112

Sheet Trade Analysis
A1: Trade Analysis: exposure and concentration
A2: Selected exporters and importers only (not the full world list). Volumes in EJ so they can be compared with domestic consumption.
A3: Prior year | B3: 2023
A4: Latest year | B4: 2024
A7: Role | B7: Country | C7: Prior year volume (EJ) | D7: Latest volume (EJ) | E7: YoY change | F7: Prior share of world trade (%) | G7: Latest share of world trade (%) | H7: Share change (pp) | I7: Reported in both years? | J7: Domestic consumption, latest (EJ) | K7: Trade / domestic consumption (x) | L7: Read-across
A8: Exporter | B8: Indonesia | C8: =IF(COUNTIFS(Data_Trade!$A$2:$A$200,$B$3,Data_Trade!$B$2:$B$200,$A8,Data_Trade!$C$2:$C$200,$B8)=0,"n/a",SUMIFS(Data_Trade!$D$2:$D$200,Data_Trade!$A$2:$A$200,$B$3,Data_Trade!$B$2:$B$200,$A8,Data_Trade!$C$2:$C$200,$B8)) -> 10 | D8: =IF(COUNTIFS(Data_Trade!$A$2:$A$200,$B$4,Data_Trade!$B$2:$B$200,$A8,Data_Trade!$C$2:$C$200,$B8)=0,"n/a",SUMIFS(Data_Trade!$D$2:$D$200,Data_Trade!$A$2:$A$200,$B$4,Data_Trade!$B$2:$B$200,$A8,Data_Trade!$C$2:$C$200,$B8)) -> 10.72 | E8: =IF(AND(ISNUMBER(C8),ISNUMBER(D8)),D8/C8-1,"n/a") -> 0.072 | F8: =IF(COUNTIFS(Data_Trade!$A$2:$A$200,$B$3,Data_Trade!$B$2:$B$200,$A8,Data_Trade!$C$2:$C$200,$B8)=0,"n/a",SUMIFS(Data_Trade!$E$2:$E$200,Data_Trade!$A$2:$A$200,$B$3,Data_Trade!$B$2:$B$200,$A8,Data_Trade!$C$2:$C$200,$B8)) -> 28.2 | G8: =IF(COUNTIFS(Data_Trade!$A$2:$A$200,$B$4,Data_Trade!$B$2:$B$200,$A8,Data_Trade!$C$2:$C$200,$B8)=0,"n/a",SUMIFS(Data_Trade!$E$2:$E$200,Data_Trade!$A$2:$A$200,$B$4,Data_Trade!$B$2:$B$200,$A8,Data_Trade!$C$2:$C$200,$B8)) -> 29.8 | H8: =IF(AND(ISNUMBER(F8),ISNUMBER(G8)),G8-F8,"n/a") -> 1.6 | I8: =IF(AND(ISNUMBER(C8),ISNUMBER(D8)),"Yes","No") -> Yes | J8: =IFERROR(INDEX(Data_Market!$D$2:$D$500,MATCH($B8&"|"&$B$4,Data_Market!$E$2:$E$500,0)),"n/a") -> 4.72 | K8: =IF(AND(ISNUMBER(D8),ISNUMBER(J8)),D8/J8,"n/a") -> 2.2711864 | L8: =IF(I8="No","Missing in one year: excluded from comparisons",IF(E8>0.05,"Volume up more than 5%",IF(E8<-0.02,"Volume down","Broadly stable"))) -> Volume up more than 5%
A9: Exporter | B9: Australia | C9: =IF(COUNTIFS(Data_Trade!$A$2:$A$200,$B$3,Data_Trade!$B$2:$B$200,$A9,Data_Trade!$C$2:$C$200,$B9)=0,"n/a",SUMIFS(Data_Trade!$D$2:$D$200,Data_Trade!$A$2:$A$200,$B$3,Data_Trade!$B$2:$B$200,$A9,Data_Trade!$C$2:$C$200,$B9)) -> 9 | D9: =IF(COUNTIFS(Data_Trade!$A$2:$A$200,$B$4,Data_Trade!$B$2:$B$200,$A9,Data_Trade!$C$2:$C$200,$B9)=0,"n/a",SUMIFS(Data_Trade!$D$2:$D$200,Data_Trade!$A$2:$A$200,$B$4,Data_Trade!$B$2:$B$200,$A9,Data_Trade!$C$2:$C$200,$B9)) -> 9.07 | E9: =IF(AND(ISNUMBER(C9),ISNUMBER(D9)),D9/C9-1,"n/a") -> 0.0077777778 | F9: =IF(COUNTIFS(Data_Trade!$A$2:$A$200,$B$3,Data_Trade!$B$2:$B$200,$A9,Data_Trade!$C$2:$C$200,$B9)=0,"n/a",SUMIFS(Data_Trade!$E$2:$E$200,Data_Trade!$A$2:$A$200,$B$3,Data_Trade!$B$2:$B$200,$A9,Data_Trade!$C$2:$C$200,$B9)) -> 25.4 | G9: =IF(COUNTIFS(Data_Trade!$A$2:$A$200,$B$4,Data_Trade!$B$2:$B$200,$A9,Data_Trade!$C$2:$C$200,$B9)=0,"n/a",SUMIFS(Data_Trade!$E$2:$E$200,Data_Trade!$A$2:$A$200,$B$4,Data_Trade!$B$2:$B$200,$A9,Data_Trade!$C$2:$C$200,$B9)) -> 25.2 | H9: =IF(AND(ISNUMBER(F9),ISNUMBER(G9)),G9-F9,"n/a") -> -0.2 | I9: =IF(AND(ISNUMBER(C9),ISNUMBER(D9)),"Yes","No") -> Yes | J9: =IFERROR(INDEX(Data_Market!$D$2:$D$500,MATCH($B9&"|"&$B$4,Data_Market!$E$2:$E$500,0)),"n/a") -> 1.52 | K9: =IF(AND(ISNUMBER(D9),ISNUMBER(J9)),D9/J9,"n/a") -> 5.9671053 | L9: =IF(I9="No","Missing in one year: excluded from comparisons",IF(E9>0.05,"Volume up more than 5%",IF(E9<-0.02,"Volume down","Broadly stable"))) -> Broadly stable
A10: Exporter | B10: Russian Federation | C10: =IF(COUNTIFS(Data_Trade!$A$2:$A$200,$B$3,Data_Trade!$B$2:$B$200,$A10,Data_Trade!$C$2:$C$200,$B10)=0,"n/a",SUMIFS(Data_Trade!$D$2:$D$200,Data_Trade!$A$2:$A$200,$B$3,Data_Trade!$B$2:$B$200,$A10,Data_Trade!$C$2:$C$200,$B10)) -> 5.39 | D10: =IF(COUNTIFS(Data_Trade!$A$2:$A$200,$B$4,Data_Trade!$B$2:$B$200,$A10,Data_Trade!$C$2:$C$200,$B10)=0,"n/a",SUMIFS(Data_Trade!$D$2:$D$200,Data_Trade!$A$2:$A$200,$B$4,Data_Trade!$B$2:$B$200,$A10,Data_Trade!$C$2:$C$200,$B10)) -> n/a | E10: =IF(AND(ISNUMBER(C10),ISNUMBER(D10)),D10/C10-1,"n/a") -> n/a | F10: =IF(COUNTIFS(Data_Trade!$A$2:$A$200,$B$3,Data_Trade!$B$2:$B$200,$A10,Data_Trade!$C$2:$C$200,$B10)=0,"n/a",SUMIFS(Data_Trade!$E$2:$E$200,Data_Trade!$A$2:$A$200,$B$3,Data_Trade!$B$2:$B$200,$A10,Data_Trade!$C$2:$C$200,$B10)) -> 15.2 | G10: =IF(COUNTIFS(Data_Trade!$A$2:$A$200,$B$4,Data_Trade!$B$2:$B$200,$A10,Data_Trade!$C$2:$C$200,$B10)=0,"n/a",SUMIFS(Data_Trade!$E$2:$E$200,Data_Trade!$A$2:$A$200,$B$4,Data_Trade!$B$2:$B$200,$A10,Data_Trade!$C$2:$C$200,$B10)) -> n/a | H10: =IF(AND(ISNUMBER(F10),ISNUMBER(G10)),G10-F10,"n/a") -> n/a | I10: =IF(AND(ISNUMBER(C10),ISNUMBER(D10)),"Yes","No") -> No | J10: =IFERROR(INDEX(Data_Market!$D$2:$D$500,MATCH($B10&"|"&$B$4,Data_Market!$E$2:$E$500,0)),"n/a") -> n/a | K10: =IF(AND(ISNUMBER(D10),ISNUMBER(J10)),D10/J10,"n/a") -> n/a | L10: =IF(I10="No","Missing in one year: excluded from comparisons",IF(E10>0.05,"Volume up more than 5%",IF(E10<-0.02,"Volume down","Broadly stable"))) -> Missing in one year: excluded from comparisons
A11: Importer | B11: China | C11: =IF(COUNTIFS(Data_Trade!$A$2:$A$200,$B$3,Data_Trade!$B$2:$B$200,$A11,Data_Trade!$C$2:$C$200,$B11)=0,"n/a",SUMIFS(Data_Trade!$D$2:$D$200,Data_Trade!$A$2:$A$200,$B$3,Data_Trade!$B$2:$B$200,$A11,Data_Trade!$C$2:$C$200,$B11)) -> 10.16 | D11: =IF(COUNTIFS(Data_Trade!$A$2:$A$200,$B$4,Data_Trade!$B$2:$B$200,$A11,Data_Trade!$C$2:$C$200,$B11)=0,"n/a",SUMIFS(Data_Trade!$D$2:$D$200,Data_Trade!$A$2:$A$200,$B$4,Data_Trade!$B$2:$B$200,$A11,Data_Trade!$C$2:$C$200,$B11)) -> 11.62 | E11: =IF(AND(ISNUMBER(C11),ISNUMBER(D11)),D11/C11-1,"n/a") -> 0.14370079 | F11: =IF(COUNTIFS(Data_Trade!$A$2:$A$200,$B$3,Data_Trade!$B$2:$B$200,$A11,Data_Trade!$C$2:$C$200,$B11)=0,"n/a",SUMIFS(Data_Trade!$E$2:$E$200,Data_Trade!$A$2:$A$200,$B$3,Data_Trade!$B$2:$B$200,$A11,Data_Trade!$C$2:$C$200,$B11)) -> 28.7 | G11: =IF(COUNTIFS(Data_Trade!$A$2:$A$200,$B$4,Data_Trade!$B$2:$B$200,$A11,Data_Trade!$C$2:$C$200,$B11)=0,"n/a",SUMIFS(Data_Trade!$E$2:$E$200,Data_Trade!$A$2:$A$200,$B$4,Data_Trade!$B$2:$B$200,$A11,Data_Trade!$C$2:$C$200,$B11)) -> 32.3 | H11: =IF(AND(ISNUMBER(F11),ISNUMBER(G11)),G11-F11,"n/a") -> 3.6 | I11: =IF(AND(ISNUMBER(C11),ISNUMBER(D11)),"Yes","No") -> Yes | J11: =IFERROR(INDEX(Data_Market!$D$2:$D$500,MATCH($B11&"|"&$B$4,Data_Market!$E$2:$E$500,0)),"n/a") -> 92.16 | K11: =IF(AND(ISNUMBER(D11),ISNUMBER(J11)),D11/J11,"n/a") -> 0.12608507 | L11: =IF(I11="No","Missing in one year: excluded from comparisons",IF(E11>0.05,"Volume up more than 5%",IF(E11<-0.02,"Volume down","Broadly stable"))) -> Volume up more than 5%
A12: Importer | B12: India | C12: =IF(COUNTIFS(Data_Trade!$A$2:$A$200,$B$3,Data_Trade!$B$2:$B$200,$A12,Data_Trade!$C$2:$C$200,$B12)=0,"n/a",SUMIFS(Data_Trade!$D$2:$D$200,Data_Trade!$A$2:$A$200,$B$3,Data_Trade!$B$2:$B$200,$A12,Data_Trade!$C$2:$C$200,$B12)) -> 5.35 | D12: =IF(COUNTIFS(Data_Trade!$A$2:$A$200,$B$4,Data_Trade!$B$2:$B$200,$A12,Data_Trade!$C$2:$C$200,$B12)=0,"n/a",SUMIFS(Data_Trade!$D$2:$D$200,Data_Trade!$A$2:$A$200,$B$4,Data_Trade!$B$2:$B$200,$A12,Data_Trade!$C$2:$C$200,$B12)) -> 5.3 | E12: =IF(AND(ISNUMBER(C12),ISNUMBER(D12)),D12/C12-1,"n/a") -> -0.0093457944 | F12: =IF(COUNTIFS(Data_Trade!$A$2:$A$200,$B$3,Data_Trade!$B$2:$B$200,$A12,Data_Trade!$C$2:$C$200,$B12)=0,"n/a",SUMIFS(Data_Trade!$E$2:$E$200,Data_Trade!$A$2:$A$200,$B$3,Data_Trade!$B$2:$B$200,$A12,Data_Trade!$C$2:$C$200,$B12)) -> 15.1 | G12: =IF(COUNTIFS(Data_Trade!$A$2:$A$200,$B$4,Data_Trade!$B$2:$B$200,$A12,Data_Trade!$C$2:$C$200,$B12)=0,"n/a",SUMIFS(Data_Trade!$E$2:$E$200,Data_Trade!$A$2:$A$200,$B$4,Data_Trade!$B$2:$B$200,$A12,Data_Trade!$C$2:$C$200,$B12)) -> 14.7 | H12: =IF(AND(ISNUMBER(F12),ISNUMBER(G12)),G12-F12,"n/a") -> -0.4 | I12: =IF(AND(ISNUMBER(C12),ISNUMBER(D12)),"Yes","No") -> Yes | J12: =IFERROR(INDEX(Data_Market!$D$2:$D$500,MATCH($B12&"|"&$B$4,Data_Market!$E$2:$E$500,0)),"n/a") -> 22.97 | K12: =IF(AND(ISNUMBER(D12),ISNUMBER(J12)),D12/J12,"n/a") -> 0.23073574 | L12: =IF(I12="No","Missing in one year: excluded from comparisons",IF(E12>0.05,"Volume up more than 5%",IF(E12<-0.02,"Volume down","Broadly stable"))) -> Broadly stable
A13: Importer | B13: Japan | C13: =IF(COUNTIFS(Data_Trade!$A$2:$A$200,$B$3,Data_Trade!$B$2:$B$200,$A13,Data_Trade!$C$2:$C$200,$B13)=0,"n/a",SUMIFS(Data_Trade!$D$2:$D$200,Data_Trade!$A$2:$A$200,$B$3,Data_Trade!$B$2:$B$200,$A13,Data_Trade!$C$2:$C$200,$B13)) -> 4.39 | D13: =IF(COUNTIFS(Data_Trade!$A$2:$A$200,$B$4,Data_Trade!$B$2:$B$200,$A13,Data_Trade!$C$2:$C$200,$B13)=0,"n/a",SUMIFS(Data_Trade!$D$2:$D$200,Data_Trade!$A$2:$A$200,$B$4,Data_Trade!$B$2:$B$200,$A13,Data_Trade!$C$2:$C$200,$B13)) -> 4.35 | E13: =IF(AND(ISNUMBER(C13),ISNUMBER(D13)),D13/C13-1,"n/a") -> -0.0091116173 | F13: =IF(COUNTIFS(Data_Trade!$A$2:$A$200,$B$3,Data_Trade!$B$2:$B$200,$A13,Data_Trade!$C$2:$C$200,$B13)=0,"n/a",SUMIFS(Data_Trade!$E$2:$E$200,Data_Trade!$A$2:$A$200,$B$3,Data_Trade!$B$2:$B$200,$A13,Data_Trade!$C$2:$C$200,$B13)) -> 12.4 | G13: =IF(COUNTIFS(Data_Trade!$A$2:$A$200,$B$4,Data_Trade!$B$2:$B$200,$A13,Data_Trade!$C$2:$C$200,$B13)=0,"n/a",SUMIFS(Data_Trade!$E$2:$E$200,Data_Trade!$A$2:$A$200,$B$4,Data_Trade!$B$2:$B$200,$A13,Data_Trade!$C$2:$C$200,$B13)) -> 12.1 | H13: =IF(AND(ISNUMBER(F13),ISNUMBER(G13)),G13-F13,"n/a") -> -0.3 | I13: =IF(AND(ISNUMBER(C13),ISNUMBER(D13)),"Yes","No") -> Yes | J13: =IFERROR(INDEX(Data_Market!$D$2:$D$500,MATCH($B13&"|"&$B$4,Data_Market!$E$2:$E$500,0)),"n/a") -> 4.53 | K13: =IF(AND(ISNUMBER(D13),ISNUMBER(J13)),D13/J13,"n/a") -> 0.9602649 | L13: =IF(I13="No","Missing in one year: excluded from comparisons",IF(E13>0.05,"Volume up more than 5%",IF(E13<-0.02,"Volume down","Broadly stable"))) -> Broadly stable
A14: Importer | B14: South Korea | C14: =IF(COUNTIFS(Data_Trade!$A$2:$A$200,$B$3,Data_Trade!$B$2:$B$200,$A14,Data_Trade!$C$2:$C$200,$B14)=0,"n/a",SUMIFS(Data_Trade!$D$2:$D$200,Data_Trade!$A$2:$A$200,$B$3,Data_Trade!$B$2:$B$200,$A14,Data_Trade!$C$2:$C$200,$B14)) -> 3.19 | D14: =IF(COUNTIFS(Data_Trade!$A$2:$A$200,$B$4,Data_Trade!$B$2:$B$200,$A14,Data_Trade!$C$2:$C$200,$B14)=0,"n/a",SUMIFS(Data_Trade!$D$2:$D$200,Data_Trade!$A$2:$A$200,$B$4,Data_Trade!$B$2:$B$200,$A14,Data_Trade!$C$2:$C$200,$B14)) -> 3.07 | E14: =IF(AND(ISNUMBER(C14),ISNUMBER(D14)),D14/C14-1,"n/a") -> -0.037617555 | F14: =IF(COUNTIFS(Data_Trade!$A$2:$A$200,$B$3,Data_Trade!$B$2:$B$200,$A14,Data_Trade!$C$2:$C$200,$B14)=0,"n/a",SUMIFS(Data_Trade!$E$2:$E$200,Data_Trade!$A$2:$A$200,$B$3,Data_Trade!$B$2:$B$200,$A14,Data_Trade!$C$2:$C$200,$B14)) -> 9 | G14: =IF(COUNTIFS(Data_Trade!$A$2:$A$200,$B$4,Data_Trade!$B$2:$B$200,$A14,Data_Trade!$C$2:$C$200,$B14)=0,"n/a",SUMIFS(Data_Trade!$E$2:$E$200,Data_Trade!$A$2:$A$200,$B$4,Data_Trade!$B$2:$B$200,$A14,Data_Trade!$C$2:$C$200,$B14)) -> 8.5 | H14: =IF(AND(ISNUMBER(F14),ISNUMBER(G14)),G14-F14,"n/a") -> -0.5 | I14: =IF(AND(ISNUMBER(C14),ISNUMBER(D14)),"Yes","No") -> Yes | J14: =IFERROR(INDEX(Data_Market!$D$2:$D$500,MATCH($B14&"|"&$B$4,Data_Market!$E$2:$E$500,0)),"n/a") -> n/a | K14: =IF(AND(ISNUMBER(D14),ISNUMBER(J14)),D14/J14,"n/a") -> n/a | L14: =IF(I14="No","Missing in one year: excluded from comparisons",IF(E14>0.05,"Volume up more than 5%",IF(E14<-0.02,"Volume down","Broadly stable"))) -> Volume down
A16: Concentration of selected trade
A17: Role | B17: Year | C17: Countries listed | D17: Combined share listed (%) | E17: Top single share (%) | F17: HHI (listed only, lower bound) | G17: Share of countries reported in both years (%)
A18: Exporter | B18: =$B$3 -> 2023 | C18: =COUNTIFS(Data_Trade!$A$2:$A$200,$B18,Data_Trade!$B$2:$B$200,$A18) -> 3 | D18: =SUMIFS(Data_Trade!$E$2:$E$200,Data_Trade!$A$2:$A$200,$B18,Data_Trade!$B$2:$B$200,$A18) -> 68.8 | E18: =SUMPRODUCT(MAX((Data_Trade!$A$2:$A$200=$B18)*(Data_Trade!$B$2:$B$200=$A18)*Data_Trade!$E$2:$E$200)) -> 28.2 | F18: =SUMPRODUCT((Data_Trade!$A$2:$A$200=$B18)*(Data_Trade!$B$2:$B$200=$A18)*Data_Trade!$E$2:$E$200^2) -> 1671.44 | G18: =SUMIFS($F$8:$F$14,$A$8:$A$14,$A18,$I$8:$I$14,"Yes") -> 53.6
A19: Exporter | B19: =$B$4 -> 2024 | C19: =COUNTIFS(Data_Trade!$A$2:$A$200,$B19,Data_Trade!$B$2:$B$200,$A19) -> 2 | D19: =SUMIFS(Data_Trade!$E$2:$E$200,Data_Trade!$A$2:$A$200,$B19,Data_Trade!$B$2:$B$200,$A19) -> 55 | E19: =SUMPRODUCT(MAX((Data_Trade!$A$2:$A$200=$B19)*(Data_Trade!$B$2:$B$200=$A19)*Data_Trade!$E$2:$E$200)) -> 29.8 | F19: =SUMPRODUCT((Data_Trade!$A$2:$A$200=$B19)*(Data_Trade!$B$2:$B$200=$A19)*Data_Trade!$E$2:$E$200^2) -> 1523.08 | G19: =SUMIFS($G$8:$G$14,$A$8:$A$14,$A19,$I$8:$I$14,"Yes") -> 55
A20: Importer | B20: =$B$3 -> 2023 | C20: =COUNTIFS(Data_Trade!$A$2:$A$200,$B20,Data_Trade!$B$2:$B$200,$A20) -> 4 | D20: =SUMIFS(Data_Trade!$E$2:$E$200,Data_Trade!$A$2:$A$200,$B20,Data_Trade!$B$2:$B$200,$A20) -> 65.2 | E20: =SUMPRODUCT(MAX((Data_Trade!$A$2:$A$200=$B20)*(Data_Trade!$B$2:$B$200=$A20)*Data_Trade!$E$2:$E$200)) -> 28.7 | F20: =SUMPRODUCT((Data_Trade!$A$2:$A$200=$B20)*(Data_Trade!$B$2:$B$200=$A20)*Data_Trade!$E$2:$E$200^2) -> 1286.46 | G20: =SUMIFS($F$8:$F$14,$A$8:$A$14,$A20,$I$8:$I$14,"Yes") -> 65.2
A21: Importer | B21: =$B$4 -> 2024 | C21: =COUNTIFS(Data_Trade!$A$2:$A$200,$B21,Data_Trade!$B$2:$B$200,$A21) -> 4 | D21: =SUMIFS(Data_Trade!$E$2:$E$200,Data_Trade!$A$2:$A$200,$B21,Data_Trade!$B$2:$B$200,$A21) -> 67.6 | E21: =SUMPRODUCT(MAX((Data_Trade!$A$2:$A$200=$B21)*(Data_Trade!$B$2:$B$200=$A21)*Data_Trade!$E$2:$E$200)) -> 32.3 | F21: =SUMPRODUCT((Data_Trade!$A$2:$A$200=$B21)*(Data_Trade!$B$2:$B$200=$A21)*Data_Trade!$E$2:$E$200^2) -> 1478.04 | G21: =SUMIFS($G$8:$G$14,$A$8:$A$14,$A21,$I$8:$I$14,"Yes") -> 67.6
A22: Like-for-like comparison uses the last column: it keeps only countries reported in both years. Listed-country totals are not comparable across years because Russia is missing in 2024. HHI is a lower bound (unlisted countries add to it).
A24: Checks and counts
A25: Implied world trade, prior year (EJ) | D25: =AVERAGEIFS(Data_Trade!$F$2:$F$200,Data_Trade!$A$2:$A$200,$B$3) -> 35.433346
A26: Implied world trade, latest year (EJ) | D26: =AVERAGEIFS(Data_Trade!$F$2:$F$200,Data_Trade!$A$2:$A$200,$B$4) -> 36.010489
A27: Entries with higher volume than prior year | D27: =COUNTIFS($E$8:$E$14,">0") -> 3
A28: Entries not reported in both years | D28: =COUNTIFS($I$8:$I$14,"No") -> 1

Sheet Price Analysis
A1: Price Analysis: Australian thermal coal benchmark
A2: USD per tonne, annual averages (World Bank Pink Sheet). Historical observations only, not a forecast.
A6: Year | B6: Price (USD/t) | C6: YoY change | D6: Index (first year = 100) | E6: Vs peak year | F6: Flag
A7: =MIN(Data_Prices!$A$2:$A$200) -> 2021 | B7: =INDEX(Data_Prices!$B$2:$B$200,MATCH($A7,Data_Prices!$A$2:$A$200,0)) -> 138.1 | C7: ="n/a" -> n/a | D7: =B7/$B$7*100 -> 100 | E7: =B7/MAX($B$7:$B$11)-1 -> -0.59959409 | F7: =IF(B7=MAX($B$7:$B$11),"Peak","")
A8: =A7+1 -> 2022 | B8: =INDEX(Data_Prices!$B$2:$B$200,MATCH($A8,Data_Prices!$A$2:$A$200,0)) -> 344.9 | C8: =B8/B7-1 -> 1.4974656 | D8: =B8/$B$7*100 -> 249.74656 | E8: =B8/MAX($B$7:$B$11)-1 -> 0 | F8: =IF(B8=MAX($B$7:$B$11),"Peak","") -> Peak
A9: =A8+1 -> 2023 | B9: =INDEX(Data_Prices!$B$2:$B$200,MATCH($A9,Data_Prices!$A$2:$A$200,0)) -> 172.8 | C9: =B9/B8-1 -> -0.49898521 | D9: =B9/$B$7*100 -> 125.12672 | E9: =B9/MAX($B$7:$B$11)-1 -> -0.49898521 | F9: =IF(B9=MAX($B$7:$B$11),"Peak","")
A10: =A9+1 -> 2024 | B10: =INDEX(Data_Prices!$B$2:$B$200,MATCH($A10,Data_Prices!$A$2:$A$200,0)) -> 136.1 | C10: =B10/B9-1 -> -0.21238426 | D10: =B10/$B$7*100 -> 98.551774 | E10: =B10/MAX($B$7:$B$11)-1 -> -0.60539287 | F10: =IF(B10=MAX($B$7:$B$11),"Peak","")
A11: =A10+1 -> 2025 | B11: =INDEX(Data_Prices!$B$2:$B$200,MATCH($A11,Data_Prices!$A$2:$A$200,0)) -> 108.4 | C11: =B11/B10-1 -> -0.20352682 | D11: =B11/$B$7*100 -> 78.493845 | E11: =B11/MAX($B$7:$B$11)-1 -> -0.685706 | F11: =IF(B11=MAX($B$7:$B$11),"Peak","")
A13: Summary
A14: Peak price (USD/t) | B14: =MAX($B$7:$B$11) -> 344.9
A15: Peak year | B15: =INDEX($A$7:$A$11,MATCH(MAX($B$7:$B$11),$B$7:$B$11,0)) -> 2022
A16: Latest price (USD/t) | B16: =$B$11 -> 108.4
A17: Latest price vs peak | B17: =$B$11/MAX($B$7:$B$11)-1 -> -0.685706
A18: Latest price vs first year | B18: =$B$11/$B$7-1 -> -0.21506155
A19: Years priced below the first-year level | B19: =COUNTIFS($B$7:$B$11,"<"&$B$7) -> 2
A20: Average price over the period (USD/t) | B20: =AVERAGE($B$7:$B$11) -> 180.06
A22: Reconciliation: annual vs quarterly
A23: Mean of 2025 quarterly prices | B23: =AVERAGEIFS(Data_Prices!$F$2:$F$200,Data_Prices!$D$2:$D$200,"2025-Q*") -> 108.4
A24: 2025 annual price | B24: =INDEX(Data_Prices!$B$2:$B$200,MATCH(2025,Data_Prices!$A$2:$A$200,0)) -> 108.4
A25: Difference | B25: =B23-B24 -> 0
A26: Status | B26: =IF(ABS(B25)<0.5,"OK: annual matches quarters","Check source") -> OK: annual matches quarters
A28: Limitation: only 2021-2025 annual prices are loaded, while production/consumption cover 2014-2024. Append earlier years to Data_Prices to extend every table here.

Sheet Data_Market
A1: Year | B1: Country | C1: Production_Mt | D1: Consumption_EJ | E1: Key | G1: Source: Energy Institute Statistical Review of World Energy 2025 (data/raw/coal_production_*.csv, coal_consumption_*.csv).
A2: 2014 | B2: Australia | C2: 505.3 | D2: 1.89 | E2: =B2&"|"&A2 -> Australia|2014 | G2: Production in million tonnes (Mt). Consumption in exajoules (EJ). Blue = typed source data. Column E is a helper key for INDEX/MATCH lookups.
A3: 2015 | B3: Australia | C3: 503.7 | D3: 1.88 | E3: =B3&"|"&A3 -> Australia|2015 | G3: PivotTable: click any cell in this table, then Insert > PivotTable.
A4: 2016 | B4: Australia | C4: 502.1 | D4: 1.95 | E4: =B4&"|"&A4 -> Australia|2016
A5: 2017 | B5: Australia | C5: 487.2 | D5: 1.94 | E5: =B5&"|"&A5 -> Australia|2017
A6: 2018 | B6: Australia | C6: 502 | D6: 1.88 | E6: =B6&"|"&A6 -> Australia|2018
A7: 2019 | B7: Australia | C7: 505.4 | D7: 1.83 | E7: =B7&"|"&A7 -> Australia|2019
A8: 2020 | B8: Australia | C8: 467.9 | D8: 1.75 | E8: =B8&"|"&A8 -> Australia|2020
A9: 2021 | B9: Australia | C9: 478.8 | D9: 1.69 | E9: =B9&"|"&A9 -> Australia|2021
A10: 2022 | B10: Australia | C10: 458.5 | D10: 1.63 | E10: =B10&"|"&A10 -> Australia|2022
A11: 2023 | B11: Australia | C11: 460.4 | D11: 1.54 | E11: =B11&"|"&A11 -> Australia|2023
A12: 2024 | B12: Australia | C12: 462.9 | D12: 1.52 | E12: =B12&"|"&A12 -> Australia|2024
A13: 2014 | B13: China | C13: 3873.9 | D13: 82.45 | E13: =B13&"|"&A13 -> China|2014
A14: 2015 | B14: China | C14: 3746.5 | D14: 82.1 | E14: =B14&"|"&A14 -> China|2015
A15: 2016 | B15: China | C15: 3410.6 | D15: 80.38 | E15: =B15&"|"&A15 -> China|2016
... A56: 2024 | B56: Japan | C56: 0.5 | D56: 4.53 | E56: =B56&"|"&A56 -> Japan|2024

Sheet Data_Trade
A1: Year | B1: Trade_Role | C1: Country | D1: Trade_EJ | E1: Share_of_World_Trade_pct | F1: Implied_World_Trade_EJ | H1: Source: Energy Institute Statistical Review 2025 (data/raw/coal_trade_selected_2023_2024.csv). Selected countries only, not the full world list.
A2: 2023 | B2: Exporter | C2: Indonesia | D2: 10 | E2: 28.2 | F2: =IFERROR(D2/E2*100,"") -> 35.460993 | H2: Implied world trade = Trade_EJ / share x 100. It should be roughly the same for every row in a year (a consistency check).
A3: 2023 | B3: Exporter | C3: Australia | D3: 9 | E3: 25.4 | F3: =IFERROR(D3/E3*100,"") -> 35.433071
A4: 2023 | B4: Exporter | C4: Russian Federation | D4: 5.39 | E4: 15.2 | F4: =IFERROR(D4/E4*100,"") -> 35.460526
A5: 2023 | B5: Importer | C5: China | D5: 10.16 | E5: 28.7 | F5: =IFERROR(D5/E5*100,"") -> 35.400697
A6: 2023 | B6: Importer | C6: India | D6: 5.35 | E6: 15.1 | F6: =IFERROR(D6/E6*100,"") -> 35.430464
A7: 2023 | B7: Importer | C7: Japan | D7: 4.39 | E7: 12.4 | F7: =IFERROR(D7/E7*100,"") -> 35.403226
A8: 2023 | B8: Importer | C8: South Korea | D8: 3.19 | E8: 9 | F8: =IFERROR(D8/E8*100,"") -> 35.444444
A9: 2024 | B9: Exporter | C9: Indonesia | D9: 10.72 | E9: 29.8 | F9: =IFERROR(D9/E9*100,"") -> 35.973154
A10: 2024 | B10: Exporter | C10: Australia | D10: 9.07 | E10: 25.2 | F10: =IFERROR(D10/E10*100,"") -> 35.992063
A11: 2024 | B11: Importer | C11: China | D11: 11.62 | E11: 32.3 | F11: =IFERROR(D11/E11*100,"") -> 35.975232
A12: 2024 | B12: Importer | C12: India | D12: 5.3 | E12: 14.7 | F12: =IFERROR(D12/E12*100,"") -> 36.054422
A13: 2024 | B13: Importer | C13: Japan | D13: 4.35 | E13: 12.1 | F13: =IFERROR(D13/E13*100,"") -> 35.950413
A14: 2024 | B14: Importer | C14: South Korea | D14: 3.07 | E14: 8.5 | F14: =IFERROR(D14/E14*100,"") -> 36.117647

Sheet Data_Prices
A1: Year | B1: Australia_Thermal_Coal_USD_per_mt | D1: Period | E1: Period_Type | F1: Price_USD_per_mt | H1: Source: World Bank Commodity Price Data (Pink Sheet), Australian thermal coal, USD per tonne.
A2: 2021 | B2: 138.1 | D2: 2024-Q3 | E2: =IF(ISNUMBER(SEARCH("Q",D2)),"Quarter","Month") -> Quarter | F2: 140.8 | H2: To extend the history: append earlier years to columns A:B. The Price Analysis sheet reads the first year automatically.
A3: 2022 | B3: 344.9 | D3: 2024-Q4 | E3: =IF(ISNUMBER(SEARCH("Q",D3)),"Quarter","Month") -> Quarter | F3: 139.5
A4: 2023 | B4: 172.8 | D4: 2025-Q1 | E4: =IF(ISNUMBER(SEARCH("Q",D4)),"Quarter","Month") -> Quarter | F4: 109.8
A5: 2024 | B5: 136.1 | D5: 2025-Q2 | E5: =IF(ISNUMBER(SEARCH("Q",D5)),"Quarter","Month") -> Quarter | F5: 104
A6: 2025 | B6: 108.4 | D6: 2025-Q3 | E6: =IF(ISNUMBER(SEARCH("Q",D6)),"Quarter","Month") -> Quarter | F6: 110.5
